File: run/SLMcases/heatTransferSLM/history/stressStrain_right.dat
#Strain(-)	Stress(Pa)
0 0 0 0 0 0                   0 0 0 0 0 0
0 0 0 0 0 0                   0 0 0 0 0 0
0 0 0 0 0 0                   0 0 0 0 0 0
0 0 0 0 0 0                   0 0 0 0 0 0
0 0 0 0 0 0                   0 0 0 0 0 0
0 0 0 0 0 0                   0 0 0 0 0 0
0 0 0 0 0 0                   0 0 0 0 0 0
0 0 0 0 0 0                   0 0 0 0 0 0
0 0 0 0 0 0                   0 0 0 0 0 0
0 0 0 0 0 0                   0 0 0 0 0 0
0 0 0 0 0 0                   0 0 0 0 0 0
0 0 0 0 0 0                   0 0 0 0 0 0
0 0 0 0 0 0                   0 0 0 0 0 0
0 0 0 0 0 0                   0 0 0 0 0 0
0 0 0 0 0 0                   0 0 0 0 0 0
0 0 0 0 0 0                   0 0 0 0 0 0
0 0 0 0 0 0                   0 0 0 0 0 0
0 0 0 0 0 0                   0 0 0 0 0 0
0 0 0 0 0 0                   0 0 0 0 0 0
0 0 0 0 0 0                   0 0 0 0 0 0
0 0 0 0 0 0                   0 0 0 0 0 0
0 0 0 0 0 0                   0 0 0 0 0 0
0 0 0 0 0 0                   0 0 0 0 0 0
0 0 0 0 0 0                   0 0 0 0 0 0
0 0 0 0 0 0                   0 0 0 0 0 0
0 0 0 0 0 0                   0 0 0 0 0 0
0 0 0 0 0 0                   0 0 0 0 0 0
0 0 0 0 0 0                   0 0 0 0 0 0
0 0 0 0 0 0                   0 0 0 0 0 0
0 0 0 0 0 0                   0 0 0 0 0 0
0 0 0 0 0 0                   0 0 0 0 0 0
0 0 0 0 0 0                   0 0 0 0 0 0
0 0 0 0 0 0                   0 0 0 0 0 0
0 0 0 0 0 0                   0 0 0 0 0 0
0 0 0 0 0 0                   0 0 0 0 0 0
0 0 0 0 0 0                   0 0 0 0 0 0
0 0 0 0 0 0                   0 0 0 0 0 0
0 0 0 0 0 0                   0 0 0 0 0 0
0 0 0 0 0 0                   0 0 0 0 0 0
0 0 0 0 0 0                   0 0 0 0 0 0
0 0 0 0 0 0                   0 0 0 0 0 0
0 0 0 0 0 0                   0 0 0 0 0 0
0 0 0 0 0 0                   0 0 0 0 0 0
0 0 0 0 0 0                   0 0 0 0 0 0
0 0 0 0 0 0                   0 0 0 0 0 0
0 0 0 0 0 0                   0 0 0 0 0 0
0 0 0 0 0 0                   0 0 0 0 0 0
0 0 0 0 0 0                   0 0 0 0 0 0
0 0 0 0 0 0                   0 0 0 0 0 0
0 0 0 0 0 0                   0 0 0 0 0 0
0 0 0 0 0 0                   0 0 0 0 0 0
0 0 0 0 0 0                   0 0 0 0 0 0
0 0 0 0 0 0                   0 0 0 0 0 0
0 0 0 0 0 0                   0 0 0 0 0 0
0 0 0 0 0 0                   0 0 0 0 0 0
0 0 0 0 0 0                   0 0 0 0 0 0
0 0 0 0 0 0                   0 0 0 0 0 0
0 0 0 0 0 0                   0 0 0 0 0 0
0 0 0 0 0 0                   0 0 0 0 0 0
0 0 0 0 0 0                   0 0 0 0 0 0
0 0 0 0 0 0                   0 0 0 0 0 0
0 0 0 0 0 0                   0 0 0 0 0 0
0 0 0 0 0 0                   0 0 0 0 0 0
0 0 0 0 0 0                   0 0 0 0 0 0
0 0 0 0 0 0                   0 0 0 0 0 0
0 0 0 0 0 0                   0 0 0 0 0 0
0 0 0 0 0 0                   0 0 0 0 0 0
0 0 0 0 0 0                   0 0 0 0 0 0
0 0 0 0 0 0                   0 0 0 0 0 0
0 0 0 0 0 0                   0 0 0 0 0 0
0 0 0 0 0 0                   0 0 0 0 0 0
0 0 0 0 0 0                   0 0 0 0 0 0
0 0 0 0 0 0                   0 0 0 0 0 0
0 0 0 0 0 0                   0 0 0 0 0 0
0 0 0 0 0 0                   0 0 0 0 0 0
0 0 0 0 0 0                   0 0 0 0 0 0
0 0 0 0 0 0                   0 0 0 0 0 0
0 0 0 0 0 0                   0 0 0 0 0 0
0 0 0 0 0 0                   0 0 0 0 0 0
0 0 0 0 0 0                   0 0 0 0 0 0
0 0 0 0 0 0                   0 0 0 0 0 0
0 0 0 0 0 0                   0 0 0 0 0 0
0 0 0 0 0 0                   0 0 0 0 0 0
0 0 0 0 0 0                   0 0 0 0 0 0
0 0 0 0 0 0                   0 0 0 0 0 0
0 0 0 0 0 0                   0 0 0 0 0 0
0 0 0 0 0 0                   0 0 0 0 0 0
0 0 0 0 0 0                   0 0 0 0 0 0
0 0 0 0 0 0                   0 0 0 0 0 0
0 0 0 0 0 0                   0 0 0 0 0 0
0 0 0 0 0 0                   0 0 0 0 0 0
0 0 0 0 0 0                   0 0 0 0 0 0
0 0 0 0 0 0                   0 0 0 0 0 0
0 0 0 0 0 0                   0 0 0 0 0 0
0 0 0 0 0 0                   0 0 0 0 0 0
0 0 0 0 0 0                   0 0 0 0 0 0
0 0 0 0 0 0                   0 0 0 0 0 0
0 0 0 0 0 0                   0 0 0 0 0 0
0 0 0 0 0 0                   0 0 0 0 0 0
0 0 0 0 0 0                   0 0 0 0 0 0
0 0 0 0 0 0                   0 0 0 0 0 0
0 0 0 0 0 0                   0 0 0 0 0 0
0 0 0 0 0 0                   0 0 0 0 0 0
0 0 0 0 0 0                   0 0 0 0 0 0
0 0 0 0 0 0                   0 0 0 0 0 0
0 0 0 0 0 0                   0 0 0 0 0 0
0 0 0 0 0 0                   0 0 0 0 0 0
0 0 0 0 0 0                   0 0 0 0 0 0
0 0 0 0 0 0                   0 0 0 0 0 0
0 0 0 0 0 0                   0 0 0 0 0 0
0 0 0 0 0 0                   0 0 0 0 0 0
0 0 0 0 0 0                   0 0 0 0 0 0
0 0 0 0 0 0                   0 0 0 0 0 0
0 0 0 0 0 0                   0 0 0 0 0 0
0 0 0 0 0 0                   0 0 0 0 0 0
0 0 0 0 0 0                   0 0 0 0 0 0
0 0 0 0 0 0                   0 0 0 0 0 0
0 0 0 0 0 0                   0 0 0 0 0 0
0 0 0 0 0 0                   0 0 0 0 0 0
0 0 0 0 0 0                   0 0 0 0 0 0
0 0 0 0 0 0                   0 0 0 0 0 0
0 0 0 0 0 0                   0 0 0 0 0 0
0 0 0 0 0 0                   0 0 0 0 0 0
0 0 0 0 0 0                   0 0 0 0 0 0
0 0 0 0 0 0                   0 0 0 0 0 0
0 0 0 0 0 0                   0 0 0 0 0 0
0 0 0 0 0 0                   0 0 0 0 0 0
0 0 0 0 0 0                   0 0 0 0 0 0
0 0 0 0 0 0                   0 0 0 0 0 0
0 0 0 0 0 0                   0 0 0 0 0 0
0 0 0 0 0 0                   0 0 0 0 0 0
0 0 0 0 0 0                   0 0 0 0 0 0
0 0 0 0 0 0                   0 0 0 0 0 0
0 0 0 0 0 0                   0 0 0 0 0 0
0 0 0 0 0 0                   0 0 0 0 0 0
0 0 0 0 0 0                   0 0 0 0 0 0
0 0 0 0 0 0                   0 0 0 0 0 0
0 0 0 0 0 0                   0 0 0 0 0 0
0 0 0 0 0 0                   0 0 0 0 0 0
0 0 0 0 0 0                   0 0 0 0 0 0
0 0 0 0 0 0                   0 0 0 0 0 0
0 0 0 0 0 0                   0 0 0 0 0 0
0 0 0 0 0 0                   0 0 0 0 0 0
0 0 0 0 0 0                   0 0 0 0 0 0
0 0 0 0 0 0                   0 0 0 0 0 0
0 0 0 0 0 0                   0 0 0 0 0 0
0 0 0 0 0 0                   0 0 0 0 0 0
0 0 0 0 0 0                   0 0 0 0 0 0
0 0 0 0 0 0                   0 0 0 0 0 0
0 0 0 0 0 0                   0 0 0 0 0 0
0 0 0 0 0 0                   0 0 0 0 0 0
0 0 0 0 0 0                   0 0 0 0 0 0
0 0 0 0 0 0                   0 0 0 0 0 0
0 0 0 0 0 0                   0 0 0 0 0 0
0 0 0 0 0 0                   0 0 0 0 0 0
0 0 0 0 0 0                   0 0 0 0 0 0
0 0 0 0 0 0                   0 0 0 0 0 0
0 0 0 0 0 0                   0 0 0 0 0 0
0 0 0 0 0 0                   0 0 0 0 0 0
0 0 0 0 0 0                   0 0 0 0 0 0
0 0 0 0 0 0                   0 0 0 0 0 0
0 0 0 0 0 0                   0 0 0 0 0 0
0 0 0 0 0 0                   0 0 0 0 0 0
0 0 0 0 0 0                   0 0 0 0 0 0
0 0 0 0 0 0                   0 0 0 0 0 0
0 0 0 0 0 0                   0 0 0 0 0 0
0 0 0 0 0 0                   0 0 0 0 0 0
0 0 0 0 0 0                   0 0 0 0 0 0
0 0 0 0 0 0                   0 0 0 0 0 0
0 0 0 0 0 0                   0 0 0 0 0 0
0 0 0 0 0 0                   0 0 0 0 0 0
0 0 0 0 0 0                   0 0 0 0 0 0
0 0 0 0 0 0                   0 0 0 0 0 0
0 0 0 0 0 0                   0 0 0 0 0 0
0 0 0 0 0 0                   0 0 0 0 0 0
0 0 0 0 0 0                   0 0 0 0 0 0
0 0 0 0 0 0                   0 0 0 0 0 0
0 0 0 0 0 0                   0 0 0 0 0 0
0 0 0 0 0 0                   0 0 0 0 0 0
0 0 0 0 0 0                   0 0 0 0 0 0
0 0 0 0 0 0                   0 0 0 0 0 0
0 0 0 0 0 0                   0 0 0 0 0 0
0 0 0 0 0 0                   0 0 0 0 0 0
0 0 0 0 0 0                   0 0 0 0 0 0
0 0 0 0 0 0                   0 0 0 0 0 0
0 0 0 0 0 0                   0 0 0 0 0 0
0 0 0 0 0 0                   0 0 0 0 0 0
0 0 0 0 0 0                   0 0 0 0 0 0
0 0 0 0 0 0                   0 0 0 0 0 0
0 0 0 0 0 0                   0 0 0 0 0 0
0 0 0 0 0 0                   0 0 0 0 0 0
0 0 0 0 0 0                   0 0 0 0 0 0
0 0 0 0 0 0                   0 0 0 0 0 0
0 0 0 0 0 0                   0 0 0 0 0 0
0 0 0 0 0 0                   0 0 0 0 0 0
0 0 0 0 0 0                   0 0 0 0 0 0
0 0 0 0 0 0                   0 0 0 0 0 0
0 0 0 0 0 0                   0 0 0 0 0 0
0 0 0 0 0 0                   0 0 0 0 0 0
0 0 0 0 0 0                   0 0 0 0 0 0
0 0 0 0 0 0                   0 0 0 0 0 0
0 0 0 0 0 0                   0 0 0 0 0 0
0 0 0 0 0 0                   0 0 0 0 0 0
0 0 0 0 0 0                   0 0 0 0 0 0
0 0 0 0 0 0                   0 0 0 0 0 0
0 0 0 0 0 0                   0 0 0 0 0 0
0 0 0 0 0 0                   0 0 0 0 0 0
0 0 0 0 0 0                   0 0 0 0 0 0
0 0 0 0 0 0                   0 0 0 0 0 0
0 0 0 0 0 0                   0 0 0 0 0 0
0 0 0 0 0 0                   0 0 0 0 0 0
0 0 0 0 0 0                   0 0 0 0 0 0
0 0 0 0 0 0                   0 0 0 0 0 0
0 0 0 0 0 0                   0 0 0 0 0 0
0 0 0 0 0 0                   0 0 0 0 0 0
0 0 0 0 0 0                   0 0 0 0 0 0
0 0 0 0 0 0                   0 0 0 0 0 0
0 0 0 0 0 0                   0 0 0 0 0 0
0 0 0 0 0 0                   0 0 0 0 0 0
0 0 0 0 0 0                   0 0 0 0 0 0
0 0 0 0 0 0                   0 0 0 0 0 0
0 0 0 0 0 0                   0 0 0 0 0 0
0 0 0 0 0 0                   0 0 0 0 0 0
0 0 0 0 0 0                   0 0 0 0 0 0
0 0 0 0 0 0                   0 0 0 0 0 0
0 0 0 0 0 0                   0 0 0 0 0 0
0 0 0 0 0 0                   0 0 0 0 0 0
0 0 0 0 0 0                   0 0 0 0 0 0
0 0 0 0 0 0                   0 0 0 0 0 0
0 0 0 0 0 0                   0 0 0 0 0 0
0 0 0 0 0 0                   0 0 0 0 0 0
0 0 0 0 0 0                   0 0 0 0 0 0
0 0 0 0 0 0                   0 0 0 0 0 0
0 0 0 0 0 0                   0 0 0 0 0 0
0 0 0 0 0 0                   0 0 0 0 0 0
0 0 0 0 0 0                   0 0 0 0 0 0
0 0 0 0 0 0                   0 0 0 0 0 0
0 0 0 0 0 0                   0 0 0 0 0 0
0 0 0 0 0 0                   0 0 0 0 0 0
0 0 0 0 0 0                   0 0 0 0 0 0
0 0 0 0 0 0                   0 0 0 0 0 0
0 0 0 0 0 0                   0 0 0 0 0 0
0 0 0 0 0 0                   0 0 0 0 0 0
0 0 0 0 0 0                   0 0 0 0 0 0
0 0 0 0 0 0                   0 0 0 0 0 0
0 0 0 0 0 0                   0 0 0 0 0 0
0 0 0 0 0 0                   0 0 0 0 0 0
0 0 0 0 0 0                   0 0 0 0 0 0
0 0 0 0 0 0                   0 0 0 0 0 0
0 0 0 0 0 0                   0 0 0 0 0 0
0 0 0 0 0 0                   0 0 0 0 0 0
0 0 0 0 0 0                   0 0 0 0 0 0
0 0 0 0 0 0                   0 0 0 0 0 0
0 0 0 0 0 0                   0 0 0 0 0 0
0 0 0 0 0 0                   0 0 0 0 0 0
0 0 0 0 0 0                   0 0 0 0 0 0
0 0 0 0 0 0                   0 0 0 0 0 0
0 0 0 0 0 0                   0 0 0 0 0 0
0 0 0 0 0 0                   0 0 0 0 0 0
0 0 0 0 0 0                   0 0 0 0 0 0
0 0 0 0 0 0                   0 0 0 0 0 0
0 0 0 0 0 0                   0 0 0 0 0 0
0 0 0 0 0 0                   0 0 0 0 0 0
0 0 0 0 0 0                   0 0 0 0 0 0
0 0 0 0 0 0                   0 0 0 0 0 0
0 0 0 0 0 0                   0 0 0 0 0 0
0 0 0 0 0 0                   0 0 0 0 0 0
0 0 0 0 0 0                   0 0 0 0 0 0
0 0 0 0 0 0                   0 0 0 0 0 0
0 0 0 0 0 0                   0 0 0 0 0 0
0 0 0 0 0 0                   0 0 0 0 0 0
0 0 0 0 0 0                   0 0 0 0 0 0
0 0 0 0 0 0                   0 0 0 0 0 0
0 0 0 0 0 0                   0 0 0 0 0 0
0 0 0 0 0 0                   0 0 0 0 0 0
0 0 0 0 0 0                   0 0 0 0 0 0
0 0 0 0 0 0                   0 0 0 0 0 0
0 0 0 0 0 0                   0 0 0 0 0 0
0 0 0 0 0 0                   0 0 0 0 0 0
0 0 0 0 0 0                   0 0 0 0 0 0
0 0 0 0 0 0                   0 0 0 0 0 0
0 0 0 0 0 0                   0 0 0 0 0 0
0 0 0 0 0 0                   0 0 0 0 0 0
0 0 0 0 0 0                   0 0 0 0 0 0
0 0 0 0 0 0                   0 0 0 0 0 0
0 0 0 0 0 0                   0 0 0 0 0 0
0 0 0 0 0 0                   0 0 0 0 0 0
0 0 0 0 0 0                   0 0 0 0 0 0
0 0 0 0 0 0                   0 0 0 0 0 0
0 0 0 0 0 0                   0 0 0 0 0 0
0 0 0 0 0 0                   0 0 0 0 0 0
0 0 0 0 0 0                   0 0 0 0 0 0
0 0 0 0 0 0                   0 0 0 0 0 0
0 0 0 0 0 0                   0 0 0 0 0 0
0 0 0 0 0 0                   0 0 0 0 0 0
0 0 0 0 0 0                   0 0 0 0 0 0
0 0 0 0 0 0                   0 0 0 0 0 0
0 0 0 0 0 0                   0 0 0 0 0 0
0 0 0 0 0 0                   0 0 0 0 0 0
0 0 0 0 0 0                   0 0 0 0 0 0
0 0 0 0 0 0                   0 0 0 0 0 0
0 0 0 0 0 0                   0 0 0 0 0 0
0 0 0 0 0 0                   0 0 0 0 0 0
0 0 0 0 0 0                   0 0 0 0 0 0
0 0 0 0 0 0                   0 0 0 0 0 0
0 0 0 0 0 0                   0 0 0 0 0 0
0 0 0 0 0 0                   0 0 0 0 0 0
0 0 0 0 0 0                   0 0 0 0 0 0
0 0 0 0 0 0                   0 0 0 0 0 0
0 0 0 0 0 0                   0 0 0 0 0 0
0 0 0 0 0 0                   0 0 0 0 0 0
0 0 0 0 0 0                   0 0 0 0 0 0
0 0 0 0 0 0                   0 0 0 0 0 0
0 0 0 0 0 0                   0 0 0 0 0 0
0 0 0 0 0 0                   0 0 0 0 0 0
0 0 0 0 0 0                   0 0 0 0 0 0
0 0 0 0 0 0                   0 0 0 0 0 0
0 0 0 0 0 0                   0 0 0 0 0 0
0 0 0 0 0 0                   0 0 0 0 0 0
0 0 0 0 0 0                   0 0 0 0 0 0
0 0 0 0 0 0                   0 0 0 0 0 0
0 0 0 0 0 0                   0 0 0 0 0 0
0 0 0 0 0 0                   0 0 0 0 0 0
0 0 0 0 0 0                   0 0 0 0 0 0
0 0 0 0 0 0                   0 0 0 0 0 0
0 0 0 0 0 0                   0 0 0 0 0 0
0 0 0 0 0 0                   0 0 0 0 0 0
0 0 0 0 0 0                   0 0 0 0 0 0
0 0 0 0 0 0                   0 0 0 0 0 0
0 0 0 0 0 0                   0 0 0 0 0 0
0 0 0 0 0 0                   0 0 0 0 0 0
0 0 0 0 0 0                   0 0 0 0 0 0
0 0 0 0 0 0                   0 0 0 0 0 0
0 0 0 0 0 0                   0 0 0 0 0 0
0 0 0 0 0 0                   0 0 0 0 0 0
0 0 0 0 0 0                   0 0 0 0 0 0
0 0 0 0 0 0                   0 0 0 0 0 0
0 0 0 0 0 0                   0 0 0 0 0 0
0 0 0 0 0 0                   0 0 0 0 0 0
0 0 0 0 0 0                   0 0 0 0 0 0
0 0 0 0 0 0                   0 0 0 0 0 0
0 0 0 0 0 0                   0 0 0 0 0 0
0 0 0 0 0 0                   0 0 0 0 0 0
0 0 0 0 0 0                   0 0 0 0 0 0
0 0 0 0 0 0                   0 0 0 0 0 0
0 0 0 0 0 0                   0 0 0 0 0 0
0 0 0 0 0 0                   0 0 0 0 0 0
0 0 0 0 0 0                   0 0 0 0 0 0
0 0 0 0 0 0                   0 0 0 0 0 0
0 0 0 0 0 0                   0 0 0 0 0 0
0 0 0 0 0 0                   0 0 0 0 0 0
0 0 0 0 0 0                   0 0 0 0 0 0
0 0 0 0 0 0                   0 0 0 0 0 0
0 0 0 0 0 0                   0 0 0 0 0 0
0 0 0 0 0 0                   0 0 0 0 0 0
0 0 0 0 0 0                   0 0 0 0 0 0
0 0 0 0 0 0                   0 0 0 0 0 0
0 0 0 0 0 0                   0 0 0 0 0 0
0 0 0 0 0 0                   0 0 0 0 0 0
0 0 0 0 0 0                   0 0 0 0 0 0
0 0 0 0 0 0                   0 0 0 0 0 0
0 0 0 0 0 0                   0 0 0 0 0 0
0 0 0 0 0 0                   0 0 0 0 0 0
0 0 0 0 0 0                   0 0 0 0 0 0
0 0 0 0 0 0                   0 0 0 0 0 0
0 0 0 0 0 0                   0 0 0 0 0 0
0 0 0 0 0 0                   0 0 0 0 0 0
0 0 0 0 0 0                   0 0 0 0 0 0
0 0 0 0 0 0                   0 0 0 0 0 0
0 0 0 0 0 0                   0 0 0 0 0 0
0 0 0 0 0 0                   0 0 0 0 0 0
0 0 0 0 0 0                   0 0 0 0 0 0
0 0 0 0 0 0                   0 0 0 0 0 0
0 0 0 0 0 0                   0 0 0 0 0 0
0 0 0 0 0 0                   0 0 0 0 0 0
0 0 0 0 0 0                   0 0 0 0 0 0
0 0 0 0 0 0                   0 0 0 0 0 0
0 0 0 0 0 0                   0 0 0 0 0 0
0 0 0 0 0 0                   0 0 0 0 0 0
0 0 0 0 0 0                   0 0 0 0 0 0
0 0 0 0 0 0                   0 0 0 0 0 0
0 0 0 0 0 0                   0 0 0 0 0 0
0 0 0 0 0 0                   0 0 0 0 0 0
0 0 0 0 0 0                   0 0 0 0 0 0
0 0 0 0 0 0                   0 0 0 0 0 0
0 0 0 0 0 0                   0 0 0 0 0 0
0 0 0 0 0 0                   0 0 0 0 0 0
0 0 0 0 0 0                   0 0 0 0 0 0
0 0 0 0 0 0                   0 0 0 0 0 0
0 0 0 0 0 0                   0 0 0 0 0 0
0 0 0 0 0 0                   0 0 0 0 0 0
0 0 0 0 0 0                   0 0 0 0 0 0
0 0 0 0 0 0                   0 0 0 0 0 0
0 0 0 0 0 0                   0 0 0 0 0 0
0 0 0 0 0 0                   0 0 0 0 0 0
0 0 0 0 0 0                   0 0 0 0 0 0
0 0 0 0 0 0                   0 0 0 0 0 0
0 0 0 0 0 0                   0 0 0 0 0 0
0 0 0 0 0 0                   0 0 0 0 0 0
0 0 0 0 0 0                   0 0 0 0 0 0
0 0 0 0 0 0                   0 0 0 0 0 0
0 0 0 0 0 0                   0 0 0 0 0 0
0 0 0 0 0 0                   0 0 0 0 0 0
0 0 0 0 0 0                   0 0 0 0 0 0
0 0 0 0 0 0                   0 0 0 0 0 0
0 0 0 0 0 0                   0 0 0 0 0 0
0 0 0 0 0 0                   0 0 0 0 0 0
0 0 0 0 0 0                   0 0 0 0 0 0
0 0 0 0 0 0                   0 0 0 0 0 0
0 0 0 0 0 0                   0 0 0 0 0 0
0 0 0 0 0 0                   0 0 0 0 0 0
0 0 0 0 0 0                   0 0 0 0 0 0
0 0 0 0 0 0                   0 0 0 0 0 0
0 0 0 0 0 0                   0 0 0 0 0 0
0 0 0 0 0 0                   0 0 0 0 0 0
0 0 0 0 0 0                   0 0 0 0 0 0
0 0 0 0 0 0                   0 0 0 0 0 0
0 0 0 0 0 0                   0 0 0 0 0 0
0 0 0 0 0 0                   0 0 0 0 0 0
0 0 0 0 0 0                   0 0 0 0 0 0
0 0 0 0 0 0                   0 0 0 0 0 0
0 0 0 0 0 0                   0 0 0 0 0 0
0 0 0 0 0 0                   0 0 0 0 0 0
0 0 0 0 0 0                   0 0 0 0 0 0
0 0 0 0 0 0                   0 0 0 0 0 0
0 0 0 0 0 0                   0 0 0 0 0 0
0 0 0 0 0 0                   0 0 0 0 0 0
0 0 0 0 0 0                   0 0 0 0 0 0
0 0 0 0 0 0                   0 0 0 0 0 0
0 0 0 0 0 0                   0 0 0 0 0 0
0 0 0 0 0 0                   0 0 0 0 0 0
0 0 0 0 0 0                   0 0 0 0 0 0
0 0 0 0 0 0                   0 0 0 0 0 0
0 0 0 0 0 0                   0 0 0 0 0 0
0 0 0 0 0 0                   0 0 0 0 0 0
0 0 0 0 0 0                   0 0 0 0 0 0
0 0 0 0 0 0                   0 0 0 0 0 0
0 0 0 0 0 0                   0 0 0 0 0 0
0 0 0 0 0 0                   0 0 0 0 0 0
0 0 0 0 0 0                   0 0 0 0 0 0
0 0 0 0 0 0                   0 0 0 0 0 0
0 0 0 0 0 0                   0 0 0 0 0 0
0 0 0 0 0 0                   0 0 0 0 0 0
0 0 0 0 0 0                   0 0 0 0 0 0
0 0 0 0 0 0                   0 0 0 0 0 0
0 0 0 0 0 0                   0 0 0 0 0 0
0 0 0 0 0 0                   0 0 0 0 0 0
0 0 0 0 0 0                   0 0 0 0 0 0
0 0 0 0 0 0                   0 0 0 0 0 0
0 0 0 0 0 0                   0 0 0 0 0 0
0 0 0 0 0 0                   0 0 0 0 0 0
0 0 0 0 0 0                   0 0 0 0 0 0
0 0 0 0 0 0                   0 0 0 0 0 0
0 0 0 0 0 0                   0 0 0 0 0 0
0 0 0 0 0 0                   0 0 0 0 0 0
0 0 0 0 0 0                   0 0 0 0 0 0
0 0 0 0 0 0                   0 0 0 0 0 0
0 0 0 0 0 0                   0 0 0 0 0 0
0 0 0 0 0 0                   0 0 0 0 0 0
0 0 0 0 0 0                   0 0 0 0 0 0
0 0 0 0 0 0                   0 0 0 0 0 0
0 0 0 0 0 0                   0 0 0 0 0 0
0 0 0 0 0 0                   0 0 0 0 0 0
0 0 0 0 0 0                   0 0 0 0 0 0
0 0 0 0 0 0                   0 0 0 0 0 0
0 0 0 0 0 0                   0 0 0 0 0 0
0 0 0 0 0 0                   0 0 0 0 0 0
0 0 0 0 0 0                   0 0 0 0 0 0
0 0 0 0 0 0                   0 0 0 0 0 0
0 0 0 0 0 0                   0 0 0 0 0 0
0 0 0 0 0 0                   0 0 0 0 0 0
0 0 0 0 0 0                   0 0 0 0 0 0
0 0 0 0 0 0                   0 0 0 0 0 0
0 0 0 0 0 0                   0 0 0 0 0 0
0 0 0 0 0 0                   0 0 0 0 0 0
0 0 0 0 0 0                   0 0 0 0 0 0
0 0 0 0 0 0                   0 0 0 0 0 0
0 0 0 0 0 0                   0 0 0 0 0 0
0 0 0 0 0 0                   0 0 0 0 0 0
0 0 0 0 0 0                   0 0 0 0 0 0
0 0 0 0 0 0                   0 0 0 0 0 0
0 0 0 0 0 0                   0 0 0 0 0 0
0 0 0 0 0 0                   0 0 0 0 0 0
0 0 0 0 0 0                   0 0 0 0 0 0
0 0 0 0 0 0                   0 0 0 0 0 0
0 0 0 0 0 0                   0 0 0 0 0 0
0 0 0 0 0 0                   0 0 0 0 0 0
0 0 0 0 0 0                   0 0 0 0 0 0
0 0 0 0 0 0                   0 0 0 0 0 0
0 0 0 0 0 0                   0 0 0 0 0 0
0 0 0 0 0 0                   0 0 0 0 0 0
0 0 0 0 0 0                   0 0 0 0 0 0
0 0 0 0 0 0                   0 0 0 0 0 0
0 0 0 0 0 0                   0 0 0 0 0 0
0 0 0 0 0 0                   0 0 0 0 0 0
0 0 0 0 0 0                   0 0 0 0 0 0
0 0 0 0 0 0                   0 0 0 0 0 0
0 0 0 0 0 0                   0 0 0 0 0 0
0 0 0 0 0 0                   0 0 0 0 0 0
0 0 0 0 0 0                   0 0 0 0 0 0
0 0 0 0 0 0                   0 0 0 0 0 0
0 0 0 0 0 0                   0 0 0 0 0 0
0 0 0 0 0 0                   0 0 0 0 0 0
0 0 0 0 0 0                   0 0 0 0 0 0
0 0 0 0 0 0                   0 0 0 0 0 0
0 0 0 0 0 0                   0 0 0 0 0 0
0 0 0 0 0 0                   0 0 0 0 0 0
0 0 0 0 0 0                   0 0 0 0 0 0
0 0 0 0 0 0                   0 0 0 0 0 0
0 0 0 0 0 0                   0 0 0 0 0 0
0 0 0 0 0 0                   0 0 0 0 0 0
0 0 0 0 0 0                   0 0 0 0 0 0
0 0 0 0 0 0                   0 0 0 0 0 0
0 0 0 0 0 0                   0 0 0 0 0 0
0 0 0 0 0 0                   0 0 0 0 0 0
0 0 0 0 0 0                   0 0 0 0 0 0
0 0 0 0 0 0                   0 0 0 0 0 0
0 0 0 0 0 0                   0 0 0 0 0 0
0 0 0 0 0 0                   0 0 0 0 0 0
0 0 0 0 0 0                   0 0 0 0 0 0
0 0 0 0 0 0                   0 0 0 0 0 0
0 0 0 0 0 0                   0 0 0 0 0 0
0 0 0 0 0 0                   0 0 0 0 0 0
0 0 0 0 0 0                   0 0 0 0 0 0
0 0 0 0 0 0                   0 0 0 0 0 0
0 0 0 0 0 0                   0 0 0 0 0 0
0 0 0 0 0 0                   0 0 0 0 0 0
0 0 0 0 0 0                   0 0 0 0 0 0
0 0 0 0 0 0                   0 0 0 0 0 0
0 0 0 0 0 0                   0 0 0 0 0 0
0 0 0 0 0 0                   0 0 0 0 0 0
0 0 0 0 0 0                   0 0 0 0 0 0
0 0 0 0 0 0                   0 0 0 0 0 0
0 0 0 0 0 0                   0 0 0 0 0 0
0 0 0 0 0 0                   0 0 0 0 0 0
0 0 0 0 0 0                   0 0 0 0 0 0
0 0 0 0 0 0                   0 0 0 0 0 0
0 0 0 0 0 0                   0 0 0 0 0 0
0 0 0 0 0 0                   0 0 0 0 0 0
0 0 0 0 0 0                   0 0 0 0 0 0
0 0 0 0 0 0                   0 0 0 0 0 0
0 0 0 0 0 0                   0 0 0 0 0 0
0 0 0 0 0 0                   0 0 0 0 0 0
0 0 0 0 0 0                   0 0 0 0 0 0
0 0 0 0 0 0                   0 0 0 0 0 0
0 0 0 0 0 0                   0 0 0 0 0 0
0 0 0 0 0 0                   0 0 0 0 0 0
0 0 0 0 0 0                   0 0 0 0 0 0
0 0 0 0 0 0                   0 0 0 0 0 0
0 0 0 0 0 0                   0 0 0 0 0 0
0 0 0 0 0 0                   0 0 0 0 0 0
0 0 0 0 0 0                   0 0 0 0 0 0
0 0 0 0 0 0                   0 0 0 0 0 0
0 0 0 0 0 0                   0 0 0 0 0 0
0 0 0 0 0 0                   0 0 0 0 0 0
0 0 0 0 0 0                   0 0 0 0 0 0
0 0 0 0 0 0                   0 0 0 0 0 0
0 0 0 0 0 0                   0 0 0 0 0 0
0 0 0 0 0 0                   0 0 0 0 0 0
0 0 0 0 0 0                   0 0 0 0 0 0
0 0 0 0 0 0                   0 0 0 0 0 0
0 0 0 0 0 0                   0 0 0 0 0 0
0 0 0 0 0 0                   0 0 0 0 0 0
0 0 0 0 0 0                   0 0 0 0 0 0
0 0 0 0 0 0                   0 0 0 0 0 0
0 0 0 0 0 0                   0 0 0 0 0 0
0 0 0 0 0 0                   0 0 0 0 0 0
0 0 0 0 0 0                   0 0 0 0 0 0
0 0 0 0 0 0                   0 0 0 0 0 0
0 0 0 0 0 0                   0 0 0 0 0 0
0 0 0 0 0 0                   0 0 0 0 0 0
0 0 0 0 0 0                   0 0 0 0 0 0
0 0 0 0 0 0                   0 0 0 0 0 0
0 0 0 0 0 0                   0 0 0 0 0 0
0 0 0 0 0 0                   0 0 0 0 0 0
0 0 0 0 0 0                   0 0 0 0 0 0
0 0 0 0 0 0                   0 0 0 0 0 0
0 0 0 0 0 0                   0 0 0 0 0 0
0 0 0 0 0 0                   0 0 0 0 0 0
0 0 0 0 0 0                   0 0 0 0 0 0
0 0 0 0 0 0                   0 0 0 0 0 0
0 0 0 0 0 0                   0 0 0 0 0 0
0 0 0 0 0 0                   0 0 0 0 0 0
0 0 0 0 0 0                   0 0 0 0 0 0
0 0 0 0 0 0                   0 0 0 0 0 0
0 0 0 0 0 0                   0 0 0 0 0 0
0 0 0 0 0 0                   0 0 0 0 0 0
0 0 0 0 0 0                   0 0 0 0 0 0
0 0 0 0 0 0                   0 0 0 0 0 0
0 0 0 0 0 0                   0 0 0 0 0 0
0 0 0 0 0 0                   0 0 0 0 0 0
0 0 0 0 0 0                   0 0 0 0 0 0
0 0 0 0 0 0                   0 0 0 0 0 0
0 0 0 0 0 0                   0 0 0 0 0 0
0 0 0 0 0 0                   0 0 0 0 0 0
0 0 0 0 0 0                   0 0 0 0 0 0
0 0 0 0 0 0                   0 0 0 0 0 0
0 0 0 0 0 0                   0 0 0 0 0 0
0 0 0 0 0 0                   0 0 0 0 0 0
0 0 0 0 0 0                   0 0 0 0 0 0
0 0 0 0 0 0                   0 0 0 0 0 0
0 0 0 0 0 0                   0 0 0 0 0 0
0 0 0 0 0 0                   0 0 0 0 0 0
0 0 0 0 0 0                   0 0 0 0 0 0
0 0 0 0 0 0                   0 0 0 0 0 0
0 0 0 0 0 0                   0 0 0 0 0 0
0 0 0 0 0 0                   0 0 0 0 0 0
0 0 0 0 0 0                   0 0 0 0 0 0
0 0 0 0 0 0                   0 0 0 0 0 0
0 0 0 0 0 0                   0 0 0 0 0 0
0 0 0 0 0 0                   0 0 0 0 0 0
0 0 0 0 0 0                   0 0 0 0 0 0
0 0 0 0 0 0                   0 0 0 0 0 0
0 0 0 0 0 0                   0 0 0 0 0 0
0 0 0 0 0 0                   0 0 0 0 0 0
0 0 0 0 0 0                   0 0 0 0 0 0
0 0 0 0 0 0                   0 0 0 0 0 0
0 0 0 0 0 0                   0 0 0 0 0 0
0 0 0 0 0 0                   0 0 0 0 0 0
0 0 0 0 0 0                   0 0 0 0 0 0
0 0 0 0 0 0                   0 0 0 0 0 0
0 0 0 0 0 0                   0 0 0 0 0 0
0 0 0 0 0 0                   0 0 0 0 0 0
0 0 0 0 0 0                   0 0 0 0 0 0
0 0 0 0 0 0                   0 0 0 0 0 0
0 0 0 0 0 0                   0 0 0 0 0 0
0 0 0 0 0 0                   0 0 0 0 0 0
0 0 0 0 0 0                   0 0 0 0 0 0
0 0 0 0 0 0                   0 0 0 0 0 0
0 0 0 0 0 0                   0 0 0 0 0 0
0 0 0 0 0 0                   0 0 0 0 0 0
0 0 0 0 0 0                   0 0 0 0 0 0
0 0 0 0 0 0                   0 0 0 0 0 0
0 0 0 0 0 0                   0 0 0 0 0 0
0 0 0 0 0 0                   0 0 0 0 0 0
0 0 0 0 0 0                   0 0 0 0 0 0
0 0 0 0 0 0                   0 0 0 0 0 0
0 0 0 0 0 0                   0 0 0 0 0 0
0 0 0 0 0 0                   0 0 0 0 0 0
0 0 0 0 0 0                   0 0 0 0 0 0
0 0 0 0 0 0                   0 0 0 0 0 0
0 0 0 0 0 0                   0 0 0 0 0 0
0 0 0 0 0 0                   0 0 0 0 0 0
0 0 0 0 0 0                   0 0 0 0 0 0
0 0 0 0 0 0                   0 0 0 0 0 0
0 0 0 0 0 0                   0 0 0 0 0 0
0 0 0 0 0 0                   0 0 0 0 0 0
0 0 0 0 0 0                   0 0 0 0 0 0
0 0 0 0 0 0                   0 0 0 0 0 0
0 0 0 0 0 0                   0 0 0 0 0 0
0 0 0 0 0 0                   0 0 0 0 0 0
0 0 0 0 0 0                   0 0 0 0 0 0
0 0 0 0 0 0                   0 0 0 0 0 0
0 0 0 0 0 0                   0 0 0 0 0 0
0 0 0 0 0 0                   0 0 0 0 0 0
0 0 0 0 0 0                   0 0 0 0 0 0
0 0 0 0 0 0                   0 0 0 0 0 0
0 0 0 0 0 0                   0 0 0 0 0 0
0 0 0 0 0 0                   0 0 0 0 0 0
0 0 0 0 0 0                   0 0 0 0 0 0
0 0 0 0 0 0                   0 0 0 0 0 0
0 0 0 0 0 0                   0 0 0 0 0 0
0 0 0 0 0 0                   0 0 0 0 0 0
0 0 0 0 0 0                   0 0 0 0 0 0
0 0 0 0 0 0                   0 0 0 0 0 0
0 0 0 0 0 0                   0 0 0 0 0 0
0 0 0 0 0 0                   0 0 0 0 0 0
0 0 0 0 0 0                   0 0 0 0 0 0
0 0 0 0 0 0                   0 0 0 0 0 0
0 0 0 0 0 0                   0 0 0 0 0 0
0 0 0 0 0 0                   0 0 0 0 0 0
0 0 0 0 0 0                   0 0 0 0 0 0
0 0 0 0 0 0                   0 0 0 0 0 0
0 0 0 0 0 0                   0 0 0 0 0 0
0 0 0 0 0 0                   0 0 0 0 0 0
0 0 0 0 0 0                   0 0 0 0 0 0
0 0 0 0 0 0                   0 0 0 0 0 0
0 0 0 0 0 0                   0 0 0 0 0 0
0 0 0 0 0 0                   0 0 0 0 0 0
0 0 0 0 0 0                   0 0 0 0 0 0
0 0 0 0 0 0                   0 0 0 0 0 0
0 0 0 0 0 0                   0 0 0 0 0 0
0 0 0 0 0 0                   0 0 0 0 0 0
0 0 0 0 0 0                   0 0 0 0 0 0
0 0 0 0 0 0                   0 0 0 0 0 0
0 0 0 0 0 0                   0 0 0 0 0 0
0 0 0 0 0 0                   0 0 0 0 0 0
0 0 0 0 0 0                   0 0 0 0 0 0
0 0 0 0 0 0                   0 0 0 0 0 0
0 0 0 0 0 0                   0 0 0 0 0 0
0 0 0 0 0 0                   0 0 0 0 0 0
0 0 0 0 0 0                   0 0 0 0 0 0
0 0 0 0 0 0                   0 0 0 0 0 0
0 0 0 0 0 0                   0 0 0 0 0 0
0 0 0 0 0 0                   0 0 0 0 0 0
0 0 0 0 0 0                   0 0 0 0 0 0
0 0 0 0 0 0                   0 0 0 0 0 0
0 0 0 0 0 0                   0 0 0 0 0 0
0 0 0 0 0 0                   0 0 0 0 0 0
0 0 0 0 0 0                   0 0 0 0 0 0
0 0 0 0 0 0                   0 0 0 0 0 0
0 0 0 0 0 0                   0 0 0 0 0 0
0 0 0 0 0 0                   0 0 0 0 0 0
0 0 0 0 0 0                   0 0 0 0 0 0
0 0 0 0 0 0                   0 0 0 0 0 0
0 0 0 0 0 0                   0 0 0 0 0 0
0 0 0 0 0 0                   0 0 0 0 0 0
0 0 0 0 0 0                   0 0 0 0 0 0
0 0 0 0 0 0                   0 0 0 0 0 0
0 0 0 0 0 0                   0 0 0 0 0 0
0 0 0 0 0 0                   0 0 0 0 0 0
0 0 0 0 0 0                   0 0 0 0 0 0
0 0 0 0 0 0                   0 0 0 0 0 0
0 0 0 0 0 0                   0 0 0 0 0 0
0 0 0 0 0 0                   0 0 0 0 0 0
0 0 0 0 0 0                   0 0 0 0 0 0
0 0 0 0 0 0                   0 0 0 0 0 0
0 0 0 0 0 0                   0 0 0 0 0 0
0 0 0 0 0 0                   0 0 0 0 0 0
0 0 0 0 0 0                   0 0 0 0 0 0
0 0 0 0 0 0                   0 0 0 0 0 0
0 0 0 0 0 0                   0 0 0 0 0 0
0 0 0 0 0 0                   0 0 0 0 0 0
0 0 0 0 0 0                   0 0 0 0 0 0
0 0 0 0 0 0                   0 0 0 0 0 0
0 0 0 0 0 0                   0 0 0 0 0 0
0 0 0 0 0 0                   0 0 0 0 0 0
0 0 0 0 0 0                   0 0 0 0 0 0
0 0 0 0 0 0                   0 0 0 0 0 0
0 0 0 0 0 0                   0 0 0 0 0 0
0 0 0 0 0 0                   0 0 0 0 0 0
0 0 0 0 0 0                   0 0 0 0 0 0
0 0 0 0 0 0                   0 0 0 0 0 0
0 0 0 0 0 0                   0 0 0 0 0 0
0 0 0 0 0 0                   0 0 0 0 0 0
0 0 0 0 0 0                   0 0 0 0 0 0
0 0 0 0 0 0                   0 0 0 0 0 0
0 0 0 0 0 0                   0 0 0 0 0 0
0 0 0 0 0 0                   0 0 0 0 0 0
0 0 0 0 0 0                   0 0 0 0 0 0
0 0 0 0 0 0                   0 0 0 0 0 0
0 0 0 0 0 0                   0 0 0 0 0 0
0 0 0 0 0 0                   0 0 0 0 0 0
0 0 0 0 0 0                   0 0 0 0 0 0
0 0 0 0 0 0                   0 0 0 0 0 0
0 0 0 0 0 0                   0 0 0 0 0 0
0 0 0 0 0 0                   0 0 0 0 0 0
0 0 0 0 0 0                   0 0 0 0 0 0
0 0 0 0 0 0                   0 0 0 0 0 0
0 0 0 0 0 0                   0 0 0 0 0 0
0 0 0 0 0 0                   0 0 0 0 0 0
0 0 0 0 0 0                   0 0 0 0 0 0
0 0 0 0 0 0                   0 0 0 0 0 0
0 0 0 0 0 0                   0 0 0 0 0 0
0 0 0 0 0 0                   0 0 0 0 0 0
0 0 0 0 0 0                   0 0 0 0 0 0
0 0 0 0 0 0                   0 0 0 0 0 0
0 0 0 0 0 0                   0 0 0 0 0 0
0 0 0 0 0 0                   0 0 0 0 0 0
0 0 0 0 0 0                   0 0 0 0 0 0
0 0 0 0 0 0                   0 0 0 0 0 0
0 0 0 0 0 0                   0 0 0 0 0 0
0 0 0 0 0 0                   0 0 0 0 0 0
0 0 0 0 0 0                   0 0 0 0 0 0
0 0 0 0 0 0                   0 0 0 0 0 0
0 0 0 0 0 0                   0 0 0 0 0 0
0 0 0 0 0 0                   0 0 0 0 0 0
0 0 0 0 0 0                   0 0 0 0 0 0
0 0 0 0 0 0                   0 0 0 0 0 0
0 0 0 0 0 0                   0 0 0 0 0 0
0 0 0 0 0 0                   0 0 0 0 0 0
0 0 0 0 0 0                   0 0 0 0 0 0
0 0 0 0 0 0                   0 0 0 0 0 0
0 0 0 0 0 0                   0 0 0 0 0 0
0 0 0 0 0 0                   0 0 0 0 0 0
0 0 0 0 0 0                   0 0 0 0 0 0
0 0 0 0 0 0                   0 0 0 0 0 0
0 0 0 0 0 0                   0 0 0 0 0 0
0 0 0 0 0 0                   0 0 0 0 0 0
0 0 0 0 0 0                   0 0 0 0 0 0
0 0 0 0 0 0                   0 0 0 0 0 0
0 0 0 0 0 0                   0 0 0 0 0 0
0 0 0 0 0 0                   0 0 0 0 0 0
0 0 0 0 0 0                   0 0 0 0 0 0
0 0 0 0 0 0                   0 0 0 0 0 0
0 0 0 0 0 0                   0 0 0 0 0 0
0 0 0 0 0 0                   0 0 0 0 0 0
0 0 0 0 0 0                   0 0 0 0 0 0
0 0 0 0 0 0                   0 0 0 0 0 0
0 0 0 0 0 0                   0 0 0 0 0 0
0 0 0 0 0 0                   0 0 0 0 0 0
0 0 0 0 0 0                   0 0 0 0 0 0
0 0 0 0 0 0                   0 0 0 0 0 0
0 0 0 0 0 0                   0 0 0 0 0 0
0 0 0 0 0 0                   0 0 0 0 0 0
0 0 0 0 0 0                   0 0 0 0 0 0
0 0 0 0 0 0                   0 0 0 0 0 0
0 0 0 0 0 0                   0 0 0 0 0 0
0 0 0 0 0 0                   0 0 0 0 0 0
0 0 0 0 0 0                   0 0 0 0 0 0
0 0 0 0 0 0                   0 0 0 0 0 0
0 0 0 0 0 0                   0 0 0 0 0 0
0 0 0 0 0 0                   0 0 0 0 0 0
0 0 0 0 0 0                   0 0 0 0 0 0
0 0 0 0 0 0                   0 0 0 0 0 0
0 0 0 0 0 0                   0 0 0 0 0 0
0 0 0 0 0 0                   0 0 0 0 0 0
0 0 0 0 0 0                   0 0 0 0 0 0
0 0 0 0 0 0                   0 0 0 0 0 0
0 0 0 0 0 0                   0 0 0 0 0 0
0 0 0 0 0 0                   0 0 0 0 0 0
0 0 0 0 0 0                   0 0 0 0 0 0
0 0 0 0 0 0                   0 0 0 0 0 0
0 0 0 0 0 0                   0 0 0 0 0 0
0 0 0 0 0 0                   0 0 0 0 0 0
0 0 0 0 0 0                   0 0 0 0 0 0
0 0 0 0 0 0                   0 0 0 0 0 0
0 0 0 0 0 0                   0 0 0 0 0 0
0 0 0 0 0 0                   0 0 0 0 0 0
0 0 0 0 0 0                   0 0 0 0 0 0
0 0 0 0 0 0                   0 0 0 0 0 0
0 0 0 0 0 0                   0 0 0 0 0 0
0 0 0 0 0 0                   0 0 0 0 0 0
0 0 0 0 0 0                   0 0 0 0 0 0
0 0 0 0 0 0                   0 0 0 0 0 0
0 0 0 0 0 0                   0 0 0 0 0 0
0 0 0 0 0 0                   0 0 0 0 0 0
0 0 0 0 0 0                   0 0 0 0 0 0
0 0 0 0 0 0                   0 0 0 0 0 0
0 0 0 0 0 0                   0 0 0 0 0 0
0 0 0 0 0 0                   0 0 0 0 0 0
0 0 0 0 0 0                   0 0 0 0 0 0
0 0 0 0 0 0                   0 0 0 0 0 0
0 0 0 0 0 0                   0 0 0 0 0 0
0 0 0 0 0 0                   0 0 0 0 0 0
0 0 0 0 0 0                   0 0 0 0 0 0
0 0 0 0 0 0                   0 0 0 0 0 0
0 0 0 0 0 0                   0 0 0 0 0 0
0 0 0 0 0 0                   0 0 0 0 0 0
0 0 0 0 0 0                   0 0 0 0 0 0
0 0 0 0 0 0                   0 0 0 0 0 0
0 0 0 0 0 0                   0 0 0 0 0 0
0 0 0 0 0 0                   0 0 0 0 0 0
0 0 0 0 0 0                   0 0 0 0 0 0
0 0 0 0 0 0                   0 0 0 0 0 0
0 0 0 0 0 0                   0 0 0 0 0 0
0 0 0 0 0 0                   0 0 0 0 0 0
0 0 0 0 0 0                   0 0 0 0 0 0
0 0 0 0 0 0                   0 0 0 0 0 0
0 0 0 0 0 0                   0 0 0 0 0 0
0 0 0 0 0 0                   0 0 0 0 0 0
0 0 0 0 0 0                   0 0 0 0 0 0
0 0 0 0 0 0                   0 0 0 0 0 0
0 0 0 0 0 0                   0 0 0 0 0 0
0 0 0 0 0 0                   0 0 0 0 0 0
0 0 0 0 0 0                   0 0 0 0 0 0
0 0 0 0 0 0                   0 0 0 0 0 0
0 0 0 0 0 0                   0 0 0 0 0 0
0 0 0 0 0 0                   0 0 0 0 0 0
0 0 0 0 0 0                   0 0 0 0 0 0
0 0 0 0 0 0                   0 0 0 0 0 0
0 0 0 0 0 0                   0 0 0 0 0 0
0 0 0 0 0 0                   0 0 0 0 0 0
0 0 0 0 0 0                   0 0 0 0 0 0
0 0 0 0 0 0                   0 0 0 0 0 0
0 0 0 0 0 0                   0 0 0 0 0 0
0 0 0 0 0 0                   0 0 0 0 0 0
0 0 0 0 0 0                   0 0 0 0 0 0
0 0 0 0 0 0                   0 0 0 0 0 0
0 0 0 0 0 0                   0 0 0 0 0 0
0 0 0 0 0 0                   0 0 0 0 0 0
0 0 0 0 0 0                   0 0 0 0 0 0
0 0 0 0 0 0                   0 0 0 0 0 0
0 0 0 0 0 0                   0 0 0 0 0 0
0 0 0 0 0 0                   0 0 0 0 0 0
0 0 0 0 0 0                   0 0 0 0 0 0
0 0 0 0 0 0                   0 0 0 0 0 0
0 0 0 0 0 0                   0 0 0 0 0 0
0 0 0 0 0 0                   0 0 0 0 0 0
0 0 0 0 0 0                   0 0 0 0 0 0
0 0 0 0 0 0                   0 0 0 0 0 0
0 0 0 0 0 0                   0 0 0 0 0 0
0 0 0 0 0 0                   0 0 0 0 0 0
0 0 0 0 0 0                   0 0 0 0 0 0
0 0 0 0 0 0                   0 0 0 0 0 0
0 0 0 0 0 0                   0 0 0 0 0 0
0 0 0 0 0 0                   0 0 0 0 0 0
0 0 0 0 0 0                   0 0 0 0 0 0
0 0 0 0 0 0                   0 0 0 0 0 0
0 0 0 0 0 0                   0 0 0 0 0 0
0 0 0 0 0 0                   0 0 0 0 0 0
0 0 0 0 0 0                   0 0 0 0 0 0
0 0 0 0 0 0                   0 0 0 0 0 0
0 0 0 0 0 0                   0 0 0 0 0 0
0 0 0 0 0 0                   0 0 0 0 0 0
0 0 0 0 0 0                   0 0 0 0 0 0
0 0 0 0 0 0                   0 0 0 0 0 0
0 0 0 0 0 0                   0 0 0 0 0 0
0 0 0 0 0 0                   0 0 0 0 0 0
0 0 0 0 0 0                   0 0 0 0 0 0
0 0 0 0 0 0                   0 0 0 0 0 0
0 0 0 0 0 0                   0 0 0 0 0 0
0 0 0 0 0 0                   0 0 0 0 0 0
0 0 0 0 0 0                   0 0 0 0 0 0
0 0 0 0 0 0                   0 0 0 0 0 0
0 0 0 0 0 0                   0 0 0 0 0 0
0 0 0 0 0 0                   0 0 0 0 0 0
0 0 0 0 0 0                   0 0 0 0 0 0
0 0 0 0 0 0                   0 0 0 0 0 0
0 0 0 0 0 0                   0 0 0 0 0 0
0 0 0 0 0 0                   0 0 0 0 0 0
0 0 0 0 0 0                   0 0 0 0 0 0
0 0 0 0 0 0                   0 0 0 0 0 0
0 0 0 0 0 0                   0 0 0 0 0 0
0 0 0 0 0 0                   0 0 0 0 0 0
0 0 0 0 0 0                   0 0 0 0 0 0
0 0 0 0 0 0                   0 0 0 0 0 0
0 0 0 0 0 0                   0 0 0 0 0 0
0 0 0 0 0 0                   0 0 0 0 0 0
0 0 0 0 0 0                   0 0 0 0 0 0
0 0 0 0 0 0                   0 0 0 0 0 0
0 0 0 0 0 0                   0 0 0 0 0 0
0 0 0 0 0 0                   0 0 0 0 0 0
0 0 0 0 0 0                   0 0 0 0 0 0
0 0 0 0 0 0                   0 0 0 0 0 0
0 0 0 0 0 0                   0 0 0 0 0 0
0 0 0 0 0 0                   0 0 0 0 0 0
0 0 0 0 0 0                   0 0 0 0 0 0
0 0 0 0 0 0                   0 0 0 0 0 0
0 0 0 0 0 0                   0 0 0 0 0 0
0 0 0 0 0 0                   0 0 0 0 0 0
0 0 0 0 0 0                   0 0 0 0 0 0
0 0 0 0 0 0                   0 0 0 0 0 0
0 0 0 0 0 0                   0 0 0 0 0 0
0 0 0 0 0 0                   0 0 0 0 0 0
0 0 0 0 0 0                   0 0 0 0 0 0
0 0 0 0 0 0                   0 0 0 0 0 0
0 0 0 0 0 0                   0 0 0 0 0 0
0 0 0 0 0 0                   0 0 0 0 0 0
0 0 0 0 0 0                   0 0 0 0 0 0
0 0 0 0 0 0                   0 0 0 0 0 0
0 0 0 0 0 0                   0 0 0 0 0 0
0 0 0 0 0 0                   0 0 0 0 0 0
0 0 0 0 0 0                   0 0 0 0 0 0
0 0 0 0 0 0                   0 0 0 0 0 0
0 0 0 0 0 0                   0 0 0 0 0 0
0 0 0 0 0 0                   0 0 0 0 0 0
0 0 0 0 0 0                   0 0 0 0 0 0
0 0 0 0 0 0                   0 0 0 0 0 0
0 0 0 0 0 0                   0 0 0 0 0 0
0 0 0 0 0 0                   0 0 0 0 0 0
0 0 0 0 0 0                   0 0 0 0 0 0
0 0 0 0 0 0                   0 0 0 0 0 0
0 0 0 0 0 0                   0 0 0 0 0 0
0 0 0 0 0 0                   0 0 0 0 0 0
0 0 0 0 0 0                   0 0 0 0 0 0
0 0 0 0 0 0                   0 0 0 0 0 0
0 0 0 0 0 0                   0 0 0 0 0 0
0 0 0 0 0 0                   0 0 0 0 0 0
0 0 0 0 0 0                   0 0 0 0 0 0
0 0 0 0 0 0                   0 0 0 0 0 0
0 0 0 0 0 0                   0 0 0 0 0 0
0 0 0 0 0 0                   0 0 0 0 0 0
0 0 0 0 0 0                   0 0 0 0 0 0
0 0 0 0 0 0                   0 0 0 0 0 0
0 0 0 0 0 0                   0 0 0 0 0 0
0 0 0 0 0 0                   0 0 0 0 0 0
0 0 0 0 0 0                   0 0 0 0 0 0
0 0 0 0 0 0                   0 0 0 0 0 0
0 0 0 0 0 0                   0 0 0 0 0 0
0 0 0 0 0 0                   0 0 0 0 0 0
0 0 0 0 0 0                   0 0 0 0 0 0
0 0 0 0 0 0                   0 0 0 0 0 0
0 0 0 0 0 0                   0 0 0 0 0 0
0 0 0 0 0 0                   0 0 0 0 0 0
0 0 0 0 0 0                   0 0 0 0 0 0
0 0 0 0 0 0                   0 0 0 0 0 0
0 0 0 0 0 0                   0 0 0 0 0 0
0 0 0 0 0 0                   0 0 0 0 0 0
0 0 0 0 0 0                   0 0 0 0 0 0
0 0 0 0 0 0                   0 0 0 0 0 0
0 0 0 0 0 0                   0 0 0 0 0 0
0 0 0 0 0 0                   0 0 0 0 0 0
0 0 0 0 0 0                   0 0 0 0 0 0
0 0 0 0 0 0                   0 0 0 0 0 0
0 0 0 0 0 0                   0 0 0 0 0 0